Workbook

Sheet Tesla Company Analysis
B9: Tesla
B10: Company analysis

Sheet Drivers
B1: Drivers
B3: Selected case | C3: 1
B4: Company | C4: Tesla
B5: Currency | C5: USD
B6: Domestic country | C6: United States
B7: 10-year treasury yield (Sep 18 2020) | C7: 0.00697
B8: Market risk premium US | C8: 0.05
B9: Company beta (Dec 15 2020) | C9: 2.15
B10: Tesla share price (Dec 15 2020) | C10: 639.83
B11: Bond Yield (Sep 18 2020) | C11: 0.04324
B12: Corporate tax rate | C12: 0.21
B13: Expected inflation | C13: 0.02

Sheet Input --->
B13: Input --->

Sheet P&L Input
B1: P&L Input
B3: (in thousands) | C3: 2015 Act | D3: 2016 Act | E3: 2017 Act | F3: 2018 Act | G3: 2019 Act
B4: Automotive revenues | C4: 3740973 | D4: 6350766 | E4: 9641300 | F4: 18514983 | G4: 20821000
B5: Energy generation and storage | C5: 14477 | D5: 181394 | E5: 1116266 | F5: 1555244 | G5: 1531000
B6: Services and other | C6: 290575 | D6: 467972 | E6: 1001185 | F6: 1391041 | G6: 2226000
B7: Total revenues | C7: =SUM(C4:C6) -> 4046025 | D7: =SUM(D4:D6) -> 7000132 | E7: =SUM(E4:E6) -> 11758751 | F7: =SUM(F4:F6) -> 21461268 | G7: =SUM(G4:G6) -> 24578000
B8: Automotive cost of revenues | C8: -2823302 | D8: -4750081 | E8: -7432704 | F8: -14173997 | G8: -16398000
B9: Energy generation and storage cost of revenues | C9: -12287 | D9: -178332 | E9: -874538 | F9: -1364896 | G9: -1341000
B10: Services and other cost of revenues | C10: -286933 | D10: -472462 | E10: -1229022 | F10: -1880354 | G10: -2770000
B11: Gross profit | C11: =SUM(C7:C10) -> 923503 | D11: =SUM(D7:D10) -> 1599257 | E11: =SUM(E7:E10) -> 2222487 | F11: =SUM(F7:F10) -> 4042021 | G11: =SUM(G7:G10) -> 4069000
B12: Research and development | C12: -717900 | D12: -834408 | E12: -1378073 | F12: -1460370 | G12: -1343000
B13: Selling, general and administrative | C13: -922232 | D13: -1432189 | E13: -2476500 | F13: -2834491 | G13: -2646000
B14: Restructuring and other | F14: -135233 | G14: -149000
B15: EBIT | C15: =SUM(C11:C14) -> -716629 | D15: =SUM(D11:D14) -> -667340 | E15: =SUM(E11:E14) -> -1632086 | F15: =SUM(F11:F14) -> -388073 | G15: =SUM(G11:G14) -> -69000
B16: Interest income | C16: 1508 | D16: 8530 | E16: 19686 | F16: 24533 | G16: 44000
B17: Interest expense | C17: -118851 | D17: -198810 | E17: -471259 | F17: -663071 | G17: -685000
B18: Other income (expense), net | C18: -41652 | D18: 111272 | E18: -125373 | F18: 21866 | G18: 45000
B19: EBT | C19: =SUM(C15:C18) -> -875624 | D19: =SUM(D15:D18) -> -746348 | E19: =SUM(E15:E18) -> -2209032 | F19: =SUM(F15:F18) -> -1004745 | G19: =SUM(G15:G18) -> -665000
B20: Provision for income taxes | C20: -13039 | D20: -26698 | E20: -31546 | F20: -57837 | G20: -110000
B21: Net loss incl. minority interests | C21: =SUM(C19:C20) -> -888663 | D21: =SUM(D19:D20) -> -773046 | E21: =SUM(E19:E20) -> -2240578 | F21: =SUM(F19:F20) -> -1062582 | G21: =SUM(G19:G20) -> -775000
B22: Minority interests | C22: 0 | D22: 98132 | E22: 279178 | F22: 86491 | G22: -87000
B23: Net loss | C23: =SUM(C21:C22) -> -888663 | D23: =SUM(D21:D22) -> -674914 | E23: =SUM(E21:E22) -> -1961400 | F23: =SUM(F21:F22) -> -976091 | G23: =SUM(G21:G22) -> -862000
B25: KPIs
B26: Revenue % automotive y-o-y | D26: =D4/C4-1 -> 0.69762412 | E26: =E4/D4-1 -> 0.51813183 | F26: =F4/E4-1 -> 0.92038242 | G26: =G4/F4-1 -> 0.1245487
B27: Revenue % generation y-o-y | D27: =D5/C5-1 -> 11.529806 | E27: =E5/D5-1 -> 5.1538199 | F27: =F5/E5-1 -> 0.39325573 | G27: =G5/F5-1 -> -0.015588551
B28: Revenue % services y-o-y | D28: =D6/C6-1 -> 0.61050331 | E28: =E6/D6-1 -> 1.1394122 | F28: =F6/E6-1 -> 0.38939457 | G28: =G6/F6-1 -> 0.6002404
B29: GP% automotive | C29: =(C4+C8)/C4 -> 0.24530276 | D29: =(D4+D8)/D4 -> 0.25204597 | E29: =(E4+E8)/E4 -> 0.22907658 | F29: =(F4+F8)/F4 -> 0.23445801 | G29: =(G4+G8)/G4 -> 0.21242976
B30: GP% energy generation and automotive | C30: =(C5+C9)/C5 -> 0.15127444 | D30: =(D5+D9)/D5 -> 0.016880382 | E30: =(E5+E9)/E5 -> 0.21655054 | F30: =(F5+F9)/F5 -> 0.12239108 | G30: =(G5+G9)/G5 -> 0.12410189
B31: GP% services and other | C31: =(C6+C10)/C6 -> 0.012533769 | D31: =(D6+D10)/D6 -> -0.0095945911 | E31: =(E6+E10)/E6 -> -0.22756733 | F31: =(F6+F10)/F6 -> -0.3517603 | G31: =(G6+G10)/G6 -> -0.24438455
B32: Overall GP% | C32: {=SUM((C4:C6)+SUM(C8:C10))/SUM(C4:C6)} -> -1.3152516 | D32: {=SUM((D4:D6)+SUM(D8:D10))/SUM(D4:D6)} -> -1.3146171 | E32: {=SUM((E4:E6)+SUM(E8:E10))/SUM(E4:E6)} -> -1.4329788 | F32: {=SUM((F4:F6)+SUM(F8:F10))/SUM(F4:F6)} -> -1.4349792 | G32: {=SUM((G4:G6)+SUM(G8:G10))/SUM(G4:G6)} -> -1.5033363
B33: EBIT % | C33: =C15/C7 -> -0.17711927 | D33: =D15/D7 -> -0.095332488 | E33: =E15/E7 -> -0.13879756 | F33: =F15/F7 -> -0.018082482 | G33: =G15/G7 -> -0.0028073887
B34: Net loss % | C34: =C23/C7 -> -0.21963853 | D34: =D23/D7 -> -0.096414468 | E34: =E23/E7 -> -0.16680343 | F34: =F23/F7 -> -0.045481516 | G34: =G23/G7 -> -0.035072016
B35: ROA
B36: ROE

Sheet Balance Sheet Input
B1: Balance Sheet Input
B3: (in thousands) | C3: 31 Dec 2015 | D3: 31 Dec 2016 | E3: 31 Dec 2017 | F3: 31 Dec 2018 | G3: 31 Dec 2019
B4: Cash and cash equivalents | C4: 1196908 | D4: 3393216 | E4: 3367914 | F4: 3685618 | G4: 6268000
B5: Restricted cash and marketable securities | C5: 22628 | D5: 105519 | E5: 155323 | F5: 192551 | G5: 246000
B6: Accounts receivable, net | C6: 168965 | D6: 499142 | E6: 515381 | F6: 949022 | G6: 1324000
B7: Inventory | C7: 1277838 | D7: 2067454 | E7: 2263537 | F7: 3113446 | G7: 3552000
B8: Prepaid expenses and other current assets | C8: 115667 | D8: 194465 | E8: 268365 | F8: 365671 | G8: 713000
B9: Total current assets | C9: =SUM(C4:C8) -> 2782006 | D9: =SUM(D4:D8) -> 6259796 | E9: =SUM(E4:E8) -> 6570520 | F9: =SUM(F4:F8) -> 8306308 | G9: =SUM(G4:G8) -> 12103000
B10: Operating lease vehicles, net | C10: 1791403 | D10: 3134080 | E10: 4116604 | F10: 2089758 | G10: 2447000
B11: Solar energy systems, leased and to be leased, net | C11: 0 | D11: 5919880 | E11: 6347490 | F11: 6271396 | G11: 6138000
B12: Property, plant and equipment, net | C12: 3403334 | D12: 5982957 | E12: 10027522 | F12: 11330077 | G12: 10396000
B13: Operating lease right-of-use assets | C13: 0 | D13: 0 | E13: 0 | F13: 0 | G13: 1218000
B14: Intangible assets, net | C14: 12816 | D14: 376145 | E14: 361502 | F14: 282492 | G14: 339000
B15: portion | C15: 0 | D15: 506302 | E15: =456652+60237 -> 516889 | F15: 489707 | G15: 591000
B16: Restricted cash, net of current portion | C16: 31522 | D16: 268165 | E16: 441722 | F16: 398219 | G16: 269000
B17: Other assets | C17: 46858 | D17: 216751 | E17: 273123 | F17: 571657 | G17: 808000
B18: Total assets | C18: =SUM(C9:C17) -> 8067939 | D18: =SUM(D9:D17) -> 22664076 | E18: =SUM(E9:E17) -> 28655372 | F18: =SUM(F9:F17) -> 29739614 | G18: =SUM(G9:G17) -> 34309000
B19: Accounts payable | C19: 916148 | D19: 1860341 | E19: 2390250 | F19: 3404451 | G19: 3771000
B20: Accrued liabilities | C20: 422798 | D20: 1210028 | E20: 1731366 | F20: 2094253 | G20: 2905000
B21: Deferred revenue | C21: 423961 | D21: 763126 | E21: 1015253 | F21: 630292 | G21: 1163000
B22: Resale value guarantees | C22: 136831 | D22: 179504 | E22: 787333 | F22: 502840 | G22: 317000
B23: Customer deposits | C23: 283370 | D23: 663859 | E23: 853919 | F23: 792601 | G23: 726000
B24: Current portion of long-term debt and capital leases | C24: 627927 | D24: 984211 | E24: 796549 | F24: 2567699 | G24: 1785000
B25: Current portion of solar bonds issued to related
B26: parties | C26: 0 | D26: 165936 | E26: 100000 | F26: 0 | G26: 0
B27: Total current liabilities | C27: 2811035 | D27: 5827005 | E27: =SUM(E19:E26) -> 7674670 | F27: =SUM(F19:F26) -> 9992136 | G27: =SUM(G19:G26) -> 10667000
B28: Long-term debt and capital leases, net of current
B29: portion | C29: 2021093 | D29: 5860049 | E29: 9415700 | F29: 9403672 | G29: 11634000
B30: Other liabilities | C30: 2152107 | D30: 5438936 | E30: 6330414 | F30: 4586166 | G30: 4541000
B31: Total liabilities | C31: =SUM(C27:C30) -> 6984235 | D31: =SUM(D27:D30) -> 17125990 | E31: =SUM(E27:E30) -> 23420784 | F31: =SUM(F27:F30) -> 23981974 | G31: =SUM(G27:G30) -> 26842000
B32: Total stockholders' equity | C32: 1083704 | D32: 4752911 | E32: 4237242 | F32: 4923243 | G32: 6618000
B33: Noncontrolling interests in subsidiaries | C33: 0 | D33: 785175 | E33: 997346 | F33: 834397 | G33: 849000
B34: Total liabilities and equity | C34: =C31+C32+C33 -> 8067939 | D34: =D31+D32+D33 -> 22664076 | E34: =E31+E32+E33 -> 28655372 | F34: =F31+F32+F33 -> 29739614 | G34: =G31+G32+G33 -> 34309000
B36: KPIs
B37: Liquidity ratios
B38: Quick ratio | C38: =(C4+C5)/C27 -> 0.43383878 | D38: =(D4+D5)/D27 -> 0.60043453 | E38: =(E4+E5)/E27 -> 0.45907342 | F38: =(F4+F5)/F27 -> 0.38812212 | G38: =(G4+G5)/G27 -> 0.61066842
B39: Current ratio | C39: =C9/C27 -> 0.9896732 | D39: =D9/D27 -> 1.0742733 | E39: =E9/E27 -> 0.85613062 | F39: =F9/F27 -> 0.83128452 | G39: =G9/G27 -> 1.1346208
B40: DSO | C40: =C6/'P&L Input'!C7*360 -> 15.033867 | D40: =D6/'P&L Input'!D7*360 -> 25.669676 | E40: =E6/'P&L Input'!E7*360 -> 15.778645 | F40: =F6/'P&L Input'!F7*360 -> 15.919279 | G40: =G6/'P&L Input'!G7*360 -> 19.392953
B41: DIO | C41: =-C7/SUM('P&L Input'!C8:C10)*360 -> 147.32376 | D41: =-D7/SUM('P&L Input'!D8:D10)*360 -> 137.80794 | E41: =-E7/SUM('P&L Input'!E8:E10)*360 -> 85.449954 | F41: =-F7/SUM('P&L Input'!F8:F10)*360 -> 64.344949 | G41: =-G7/SUM('P&L Input'!G8:G10)*360 -> 62.349213
B42: DPO | C42: =-C19/SUM('P&L Input'!C8:C10)*360 -> 105.62401 | D42: =-D19/SUM('P&L Input'!D8:D10)*360 -> 124.00264 | E42: =-E19/SUM('P&L Input'!E8:E10)*360 -> 90.23345 | F42: =-F19/SUM('P&L Input'!F8:F10)*360 -> 70.35909 | G42: =-G19/SUM('P&L Input'!G8:G10)*360 -> 66.193379
...

Sheet Income Statement Items --->
B13: Income Statement Items --->

Sheet 1. Automotive
B13: 1. Automotive

Sheet Tesla Automotive Deliveries
B1: Tesla Automotive Deliveries
B3: Tesla Deliveries
B4: Vehicle | C4: 2015 Act | D4: 2016 Act | E4: 2017 Act | F4: 2018 Act | G4: 2019 Act | H4: 2020 Fcst | I4: 2021 Fcst | J4: 2022 Fcst | K4: 2023 Fcst | L4: 2024 Fcst | M4: 2025 Fcst | N4: 2026 Fcst | O4: 2027 Fcst | P4: 2028 Fcst | Q4: 2029 Fcst
B5: Tesla Model 3 | C5: 0 | D5: 0 | E5: 1764 | F5: 146055 | G5: 300815 | H5: =G5*(1+H15) -> 481304 | I5: =H5*(1+I15) -> 529434.4 | J5: =I5*(1+J15) -> 582377.84 | K5: =J5*(1+K15) -> 628968.07 | L5: =K5*(1+L15) -> 679285.51 | M5: =L5*(1+M15) -> 706456.93 | N5: =M5*(1+N15) -> 734715.21 | O5: =N5*(1+O15) -> 764103.82 | ... Q5: =P5*(1+Q15) -> 826454.69
B6: Tesla Model S and X | C6: 50580 | D6: 76230 | E6: 101312 | F6: 98865 | G6: 66385 | H6: =G6*(1+H16) -> 69040.4 | I6: =H6*(1+I16) -> 71802.016 | J6: =I6*(1+J16) -> 74674.097 | K6: =J6*(1+K16) -> 77661.061 | L6: =K6*(1+L16) -> 80767.503 | M6: =L6*(1+M16) -> 83998.203 | N6: =M6*(1+N16) -> 87358.131 | O6: =N6*(1+O16) -> 90852.456 | ... Q6: =P6*(1+Q16) -> 98266.017
B7: Tesla Model Y | C7: 0 | D7: 0 | E7: 0 | F7: 0 | G7: 0 | H7: =E5 -> 1764 | I7: =F5 -> 146055 | J7: =G5 -> 300815 | K7: =J7*(1+K17) -> 481304 | L7: =K7*(1+L17) -> 529434.4 | M7: =L7*(1+M17) -> 582377.84 | N7: =M7*(1+N17) -> 628968.07 | O7: =N7*(1+O17) -> 679285.51 | P7: =O7*(1+P17) -> 706456.93 | Q7: =P7*(1+Q17) -> 734715.21
B8: Tesla Roadster 2 | C8: 0 | D8: 0 | E8: 0 | F8: 0 | G8: 0 | H8: - | I8: - | J8: 500 | K8: =J8*(1+K18) -> 1000 | L8: =K8*(1+L18) -> 1500 | M8: =L8*(1+M18) -> 1650 | N8: =M8*(1+N18) -> 1815 | O8: =N8*(1+O18) -> 1960.2 | P8: =O8*(1+P18) -> 2117.016 | Q8: =P8*(1+Q18) -> 2201.6966
B9: Tesla Pickup | C9: 0 | D9: 0 | E9: 0 | F9: 0 | G9: 0 | H9: - | I9: 250 | J9: =I9*(1+J19) -> 20699.405 | K9: =J9*(1+K19) -> 42632.511 | L9: =K9*(1+L19) -> 68212.018 | M9: =L9*(1+M19) -> 75033.22 | N9: =M9*(1+N19) -> 82536.542 | O9: =N9*(1+O19) -> 89139.465 | P9: =O9*(1+P19) -> 96270.623 | Q9: =P9*(1+Q19) -> 100121.45
B10: Tesla Semi | C10: 0 | D10: 0 | E10: 0 | F10: 0 | G10: 0 | H10: - | I10: 250 | J10: =I10*(1+J20) -> 20699.405 | K10: =J10*(1+K20) -> 42632.511 | L10: =K10*(1+L20) -> 68212.018 | M10: =L10*(1+M20) -> 75033.22 | N10: =M10*(1+N20) -> 82536.542 | O10: =N10*(1+O20) -> 89139.465 | P10: =O10*(1+P20) -> 96270.623 | Q10: =P10*(1+Q20) -> 100121.45
B11: Total | C11: =SUM(C5:C10) -> 50580 | D11: =SUM(D5:D10) -> 76230 | E11: =SUM(E5:E10) -> 103076 | F11: =SUM(F5:F10) -> 244920 | G11: =SUM(G5:G10) -> 367200 | H11: =SUM(H5:H10) -> 552108.4 | I11: =SUM(I5:I10) -> 747791.42 | J11: =SUM(J5:J10) -> 999765.75 | ... Q11: =SUM(Q5:Q10) -> 1861880.5
B13: y-o-y growth %
B15: Tesla Model 3 | C15: n.a. | D15: n.a. | E15: n.a. | F15: =F5/E5-1 -> 81.797619 | G15: =G5/F5-1 -> 1.0596008 | H15: 0.6 | I15: =$C$25 -> 0.1 | J15: =$C$25 -> 0.1 | K15: =$C$26 -> 0.08 | L15: =$C$26 -> 0.08 | M15: =$C$27 -> 0.04 | N15: =$C$27 -> 0.04 | O15: =$C$27 -> 0.04 | P15: =$C$27 -> 0.04 | Q15: =$C$27 -> 0.04
B16: Tesla Model S and X | C16: n.a. | D16: =D6/C6-1 -> 0.50711744 | E16: =E6/D6-1 -> 0.32903057 | F16: =F6/E6-1 -> -0.024153111 | G16: =G6/F6-1 -> -0.3285288 | H16: =$C$27 -> 0.04 | I16: =$C$27 -> 0.04 | J16: =$C$27 -> 0.04 | K16: =$C$27 -> 0.04 | L16: =$C$27 -> 0.04 | M16: =$C$27 -> 0.04 | N16: =$C$27 -> 0.04 | O16: =$C$27 -> 0.04 | ... Q16: =$C$27 -> 0.04
B17: Tesla Model Y | C17: n.a. | D17: n.a. | E17: n.a. | F17: n.a. | G17: n.a. | H17: n.a. | I17: =F15 -> 81.797619 | J17: =G15 -> 1.0596008 | K17: =H15 -> 0.6 | L17: =I15 -> 0.1 | M17: =J15 -> 0.1 | N17: =K15 -> 0.08 | O17: =L15 -> 0.08 | P17: =M15 -> 0.04 | Q17: =N15 -> 0.04
B18: Tesla Roadster 2 | C18: n.a. | D18: n.a. | E18: n.a. | F18: n.a. | G18: n.a. | H18: n.a. | I18: n.a. | J18: n.a. | K18: 1 | L18: 0.5 | M18: =$C$25 -> 0.1 | N18: =$C$25 -> 0.1 | O18: =$C$26 -> 0.08 | P18: =$C$26 -> 0.08 | Q18: =$C$27 -> 0.04
B19: Tesla Pickup | C19: n.a. | D19: n.a. | E19: n.a. | F19: n.a. | G19: n.a. | H19: n.a. | I19: n.a. | J19: =F$15 -> 81.797619 | K19: =G$15 -> 1.0596008 | L19: =H$15 -> 0.6 | M19: =$C$25 -> 0.1 | N19: =$C$25 -> 0.1 | O19: =$C$26 -> 0.08 | P19: =$C$26 -> 0.08 | Q19: =$C$27 -> 0.04
B20: Tesla Semi | C20: n.a. | D20: n.a. | E20: n.a. | F20: n.a. | G20: n.a. | H20: n.a. | I20: n.a. | J20: =F$15 -> 81.797619 | K20: =G$15 -> 1.0596008 | L20: =H$15 -> 0.6 | M20: =$C$25 -> 0.1 | N20: =$C$25 -> 0.1 | O20: =$C$26 -> 0.08 | P20: =$C$26 -> 0.08 | Q20: =$C$27 -> 0.04
B24: Assumed growth after introduction:
B25: 2 years | C25: 0.1
B26: 2 years | C26: 0.08
B27: onwards | C27: 0.04

Sheet  Automotive Deliveries Chart
B1: Tesla Automotive Deliveries Chart

Sheet Automotive Deliverie comparable
B1: Tesla Deliveries comparables
B3: Comparables 2015-2019
B5: Vehicle Sales 2015-2019 - average | C5: Average | D5: Adj. Average
B6: GM | C6: 9600340 | D6: =C6 -> 9600340
B7: Ford | C7: 6607000 | D7: =C7 -> 6607000
B8: Fiat Chrysler | C8: 4740000 | D8: =C8 -> 4740000
B9: BMW | C9: 2460000 | D9: =C9 -> 2460000
B10: Volkswagen | C10: 10700000 | D10: =C10 -> 10700000
B11: Average | D11: =AVERAGE(D6:D10) -> 6821468
B15: Tesla Expected Deliveries
B16: 2020 | C16: ='Tesla Automotive Deliveries'!H11 -> 552108.4
B17: 2025 | C17: ='Tesla Automotive Deliveries'!M11 -> 1524549.4
B18: 2029 | C18: ='Tesla Automotive Deliveries'!Q11 -> 1861880.5

Sheet Average Automotive Model Prices
B1: Average Tesla Automative Model prices
B3: Model and Version | C3: Range | D3: Base price | E3: Fully loaded | F3: Average Price per Model
B4: Model 3 Standard Range Plus | C4: 250 miles | D4: 39990 | E4: 51490
B5: Model 3 Long Range | C5: 322 miles | D5: 48990 | E5: 60490
B6: Model 3 Performance | C6: 322 miles | D6: 56990 | E6: 66990
B7: Average Model 3 | F7: =AVERAGE(D4:E6) -> 54156.667
B8: Model S Long Range | C8: 373 miles | D8: 79990 | E8: 95490
B9: Model S Performance | C9: 348 miles | D9: 99990 | E9: 115990
B10: Model X Long Range | C10: 328 miles | D10: 84990 | E10: 106490
B11: Model X Performance | C11: 305 miles | D11: 104990 | E11: 128490
B12: Average Model S and X | F12: =AVERAGE(D8:E11) -> 102052.5
B14: Model | C14: Base price | D14: Max price
B15: CyberTruck | C15: 39900 | D15: 76900 | F15: =AVERAGE(C15:D15) -> 58400
B16: Model Y | C16: 48000 | D16: 74000 | F16: =AVERAGE(C16:D16) -> 61000
B17: Roadster 2020 | C17: 200000 | D17: 250000 | F17: =AVERAGE(C17:D17) -> 225000
B18: Semi | C18: 150000 | D18: 200000 | F18: =AVERAGE(C18:D18) -> 175000

Sheet Tesla Revenue Automotive
B1: Tesla Revenue Automotive
B3: Tesla Revenue Automotive (in mln $)
B4: Vehicle | C4: 2015 Act | D4: 2016 Act | E4: 2017 Act | F4: 2018 Act | G4: 2019 Act | H4: 2020 Fcst | I4: 2021 Fcst | J4: 2022 Fcst | K4: 2023 Fcst | L4: 2024 Fcst | M4: 2025 Fcst | N4: 2026 Fcst | O4: 2027 Fcst | P4: 2028 Fcst | Q4: 2029 Fcst | R4: Average Price ($)
B5: Tesla Model 3 | E5: 88.268789 | F5: 8136.483 | G5: 14705.599 | H5: =($R5*'Tesla Automotive Deliveries'!H5)*H14/1000000 -> 26587.137 | I5: =($R$5*'Tesla Automotive Deliveries'!I5)*I14/1000000 -> 29245.85 | J5: =($R$5*'Tesla Automotive Deliveries'!J5)*J14/1000000 -> 32170.435 | K5: =($R$5*'Tesla Automotive Deliveries'!K5)*K14/1000000 -> 34744.07 | L5: =($R$5*'Tesla Automotive Deliveries'!L5)*L14/1000000 -> 37523.596 | M5: =($R$5*'Tesla Automotive Deliveries'!M5)*M14/1000000 -> 39024.54 | N5: =($R$5*'Tesla Automotive Deliveries'!N5)*N14/1000000 -> 40585.521 | O5: =($R$5*'Tesla Automotive Deliveries'!O5)*O14/1000000 -> 42208.942 | P5: =($R$5*'Tesla Automotive Deliveries'!P5)*P14/1000000 -> 43897.3 | Q5: =($R$5*'Tesla Automotive Deliveries'!Q5)*Q14/1000000 -> 45653.192 | R5: =AVERAGE('Average Automotive Model Prices'!$F$7) -> 54156.667
B6: Tesla Model S and X | C6: 3740.973 | D6: 6350.766 | E6: 9553.0312 | F6: 10378.5 | G6: 6115.4007 | H6: =($R6*'Tesla Automotive Deliveries'!H6)*H15/1000000 -> 7186.6603 | I6: =($R6*'Tesla Automotive Deliveries'!I6)*I15/1000000 -> 7474.1267 | J6: =($R6*'Tesla Automotive Deliveries'!J6)*J15/1000000 -> 7773.0918 | K6: =($R6*'Tesla Automotive Deliveries'!K6)*K15/1000000 -> 8084.0155 | L6: =($R6*'Tesla Automotive Deliveries'!L6)*L15/1000000 -> 8407.3761 | M6: =($R6*'Tesla Automotive Deliveries'!M6)*M15/1000000 -> 8743.6711 | N6: =($R6*'Tesla Automotive Deliveries'!N6)*N15/1000000 -> 9093.418 | O6: =($R6*'Tesla Automotive Deliveries'!O6)*O15/1000000 -> 9457.1547 | ... Q6: =($R6*'Tesla Automotive Deliveries'!Q6)*Q15/1000000 -> 10228.859 | R6: =AVERAGE('Average Automotive Model Prices'!$F$12) -> 102052.5
B7: Tesla Model Y | C7: =($R7*'Tesla Automotive Deliveries'!C7)*C16/1000000 -> 0 | D7: =($R7*'Tesla Automotive Deliveries'!D7)*D16/1000000 -> 0 | E7: =($R7*'Tesla Automotive Deliveries'!E7)*E16/1000000 -> 0 | F7: =($R7*'Tesla Automotive Deliveries'!F7)*F16/1000000 -> 0 | G7: =($R7*'Tesla Automotive Deliveries'!G7)*G16/1000000 -> 0 | H7: =($R7*'Tesla Automotive Deliveries'!H7)*H16/1000000 -> 109.75608 | I7: =($R7*'Tesla Automotive Deliveries'!I7)*I16/1000000 -> 9087.5421 | J7: =($R7*'Tesla Automotive Deliveries'!J7)*J16/1000000 -> 18716.709 | ... Q7: =($R7*'Tesla Automotive Deliveries'!Q7)*Q16/1000000 -> 45713.98 | R7: =AVERAGE('Average Automotive Model Prices'!$F$16) -> 61000
B8: Tesla Roadster 2 | C8: =($R8*'Tesla Automotive Deliveries'!C8)*C17/1000000 -> 0 | D8: =($R8*'Tesla Automotive Deliveries'!D8)*D17/1000000 -> 0 | E8: =($R8*'Tesla Automotive Deliveries'!E8)*E17/1000000 -> 0 | F8: =($R8*'Tesla Automotive Deliveries'!F8)*F17/1000000 -> 0 | G8: =($R8*'Tesla Automotive Deliveries'!G8)*G17/1000000 -> 0 | H8: - | I8: - | J8: =($R8*'Tesla Automotive Deliveries'!J8)*J17/1000000 -> 114.75 | K8: =($R8*'Tesla Automotive Deliveries'!K8)*K17/1000000 -> 229.5 | L8: =($R8*'Tesla Automotive Deliveries'!L8)*L17/1000000 -> 344.25 | M8: =($R8*'Tesla Automotive Deliveries'!M8)*M17/1000000 -> 378.675 | N8: =($R8*'Tesla Automotive Deliveries'!N8)*N17/1000000 -> 416.5425 | O8: =($R8*'Tesla Automotive Deliveries'!O8)*O17/1000000 -> 449.8659 | P8: =($R8*'Tesla Automotive Deliveries'!P8)*P17/1000000 -> 485.85517 | Q8: =($R8*'Tesla Automotive Deliveries'!Q8)*Q17/1000000 -> 505.28938 | R8: =AVERAGE('Average Automotive Model Prices'!$F$17) -> 225000
B9: Tesla Pickup | C9: =($R9*'Tesla Automotive Deliveries'!C9)*C18/1000000 -> 0 | D9: =($R9*'Tesla Automotive Deliveries'!D9)*D18/1000000 -> 0 | E9: =($R9*'Tesla Automotive Deliveries'!E9)*E18/1000000 -> 0 | F9: =($R9*'Tesla Automotive Deliveries'!F9)*F18/1000000 -> 0 | G9: =($R9*'Tesla Automotive Deliveries'!G9)*G18/1000000 -> 0 | H9: - | I9: =($R9*'Tesla Automotive Deliveries'!I9)*I18/1000000 -> 14.892 | J9: =($R9*'Tesla Automotive Deliveries'!J9)*J18/1000000 -> 1233.0221 | K9: =($R9*'Tesla Automotive Deliveries'!K9)*K18/1000000 -> 2539.5334 | L9: =($R9*'Tesla Automotive Deliveries'!L9)*L18/1000000 -> 4063.2535 | M9: =($R9*'Tesla Automotive Deliveries'!M9)*M18/1000000 -> 4469.5788 | N9: =($R9*'Tesla Automotive Deliveries'!N9)*N18/1000000 -> 4916.5367 | O9: =($R9*'Tesla Automotive Deliveries'!O9)*O18/1000000 -> 5309.8597 | P9: =($R9*'Tesla Automotive Deliveries'!P9)*P18/1000000 -> 5734.6484 | Q9: =($R9*'Tesla Automotive Deliveries'!Q9)*Q18/1000000 -> 5964.0344 | R9: =AVERAGE('Average Automotive Model Prices'!$F$15) -> 58400
B10: Tesla Semi | C10: =($R10*'Tesla Automotive Deliveries'!C10)*C19/1000000 -> 0 | D10: =($R10*'Tesla Automotive Deliveries'!D10)*D19/1000000 -> 0 | E10: =($R10*'Tesla Automotive Deliveries'!E10)*E19/1000000 -> 0 | F10: =($R10*'Tesla Automotive Deliveries'!F10)*F19/1000000 -> 0 | G10: =($R10*'Tesla Automotive Deliveries'!G10)*G19/1000000 -> 0 | H10: - | I10: =($R10*'Tesla Automotive Deliveries'!I10)*I19/1000000 -> 44.625 | J10: =($R10*'Tesla Automotive Deliveries'!J10)*J19/1000000 -> 3694.8438 | K10: =($R10*'Tesla Automotive Deliveries'!K10)*K19/1000000 -> 7609.9033 | L10: =($R10*'Tesla Automotive Deliveries'!L10)*L19/1000000 -> 12175.845 | M10: =($R10*'Tesla Automotive Deliveries'!M10)*M19/1000000 -> 13393.43 | N10: =($R10*'Tesla Automotive Deliveries'!N10)*N19/1000000 -> 14732.773 | O10: =($R10*'Tesla Automotive Deliveries'!O10)*O19/1000000 -> 15911.395 | P10: =($R10*'Tesla Automotive Deliveries'!P10)*P19/1000000 -> 17184.306 | Q10: =($R10*'Tesla Automotive Deliveries'!Q10)*Q19/1000000 -> 17871.678 | R10: =AVERAGE('Average Automotive Model Prices'!$F$18) -> 175000
B11: Total | C11: =SUM(C5:C10) -> 3740.973 | D11: =SUM(D5:D10) -> 6350.766 | E11: =SUM(E5:E10) -> 9641.3 | F11: =SUM(F5:F10) -> 18514.983 | G11: =SUM(G5:G10) -> 20821 | H11: =SUM(H5:H10) -> 33883.553 | I11: =SUM(I5:I10) -> 45867.036 | J11: =SUM(J5:J10) -> 63702.852 | ... Q11: =SUM(Q5:Q10) -> 125937.03
B13: Selected case
B14: Tesla Model 3 | H14: =CHOOSE(Drivers!$C$3,'Tesla Revenue Automotive'!H22,'Tesla Revenue Automotive'!H30,'Tesla Revenue Automotive'!H38) -> 1.02 | I14: =CHOOSE(Drivers!$C$3,'Tesla Revenue Automotive'!I22,'Tesla Revenue Automotive'!I30,'Tesla Revenue Automotive'!I38) -> 1.02 | J14: =CHOOSE(Drivers!$C$3,'Tesla Revenue Automotive'!J22,'Tesla Revenue Automotive'!J30,'Tesla Revenue Automotive'!J38) -> 1.02 | K14: =CHOOSE(Drivers!$C$3,'Tesla Revenue Automotive'!K22,'Tesla Revenue Automotive'!K30,'Tesla Revenue Automotive'!K38) -> 1.02 | L14: =CHOOSE(Drivers!$C$3,'Tesla Revenue Automotive'!L22,'Tesla Revenue Automotive'!L30,'Tesla Revenue Automotive'!L38) -> 1.02 | M14: =CHOOSE(Drivers!$C$3,'Tesla Revenue Automotive'!M22,'Tesla Revenue Automotive'!M30,'Tesla Revenue Automotive'!M38) -> 1.02 | N14: =CHOOSE(Drivers!$C$3,'Tesla Revenue Automotive'!N22,'Tesla Revenue Automotive'!N30,'Tesla Revenue Automotive'!N38) -> 1.02 | O14: =CHOOSE(Drivers!$C$3,'Tesla Revenue Automotive'!O22,'Tesla Revenue Automotive'!O30,'Tesla Revenue Automotive'!O38) -> 1.02 | ... Q14: =CHOOSE(Drivers!$C$3,'Tesla Revenue Automotive'!Q22,'Tesla Revenue Automotive'!Q30,'Tesla Revenue Automotive'!Q38) -> 1.02
B15: Tesla Model S and X | H15: =CHOOSE(Drivers!$C$3,'Tesla Revenue Automotive'!H23,'Tesla Revenue Automotive'!H31,'Tesla Revenue Automotive'!H39) -> 1.02 | I15: =CHOOSE(Drivers!$C$3,'Tesla Revenue Automotive'!I23,'Tesla Revenue Automotive'!I31,'Tesla Revenue Automotive'!I39) -> 1.02 | J15: =CHOOSE(Drivers!$C$3,'Tesla Revenue Automotive'!J23,'Tesla Revenue Automotive'!J31,'Tesla Revenue Automotive'!J39) -> 1.02 | K15: =CHOOSE(Drivers!$C$3,'Tesla Revenue Automotive'!K23,'Tesla Revenue Automotive'!K31,'Tesla Revenue Automotive'!K39) -> 1.02 | L15: =CHOOSE(Drivers!$C$3,'Tesla Revenue Automotive'!L23,'Tesla Revenue Automotive'!L31,'Tesla Revenue Automotive'!L39) -> 1.02 | M15: =CHOOSE(Drivers!$C$3,'Tesla Revenue Automotive'!M23,'Tesla Revenue Automotive'!M31,'Tesla Revenue Automotive'!M39) -> 1.02 | N15: =CHOOSE(Drivers!$C$3,'Tesla Revenue Automotive'!N23,'Tesla Revenue Automotive'!N31,'Tesla Revenue Automotive'!N39) -> 1.02 | O15: =CHOOSE(Drivers!$C$3,'Tesla Revenue Automotive'!O23,'Tesla Revenue Automotive'!O31,'Tesla Revenue Automotive'!O39) -> 1.02 | ... Q15: =CHOOSE(Drivers!$C$3,'Tesla Revenue Automotive'!Q23,'Tesla Revenue Automotive'!Q31,'Tesla Revenue Automotive'!Q39) -> 1.02
B16: Tesla Model Y | H16: =CHOOSE(Drivers!$C$3,'Tesla Revenue Automotive'!H24,'Tesla Revenue Automotive'!H32,'Tesla Revenue Automotive'!H40) -> 1.02 | I16: =CHOOSE(Drivers!$C$3,'Tesla Revenue Automotive'!I24,'Tesla Revenue Automotive'!I32,'Tesla Revenue Automotive'!I40) -> 1.02 | J16: =CHOOSE(Drivers!$C$3,'Tesla Revenue Automotive'!J24,'Tesla Revenue Automotive'!J32,'Tesla Revenue Automotive'!J40) -> 1.02 | K16: =CHOOSE(Drivers!$C$3,'Tesla Revenue Automotive'!K24,'Tesla Revenue Automotive'!K32,'Tesla Revenue Automotive'!K40) -> 1.02 | L16: =CHOOSE(Drivers!$C$3,'Tesla Revenue Automotive'!L24,'Tesla Revenue Automotive'!L32,'Tesla Revenue Automotive'!L40) -> 1.02 | M16: =CHOOSE(Drivers!$C$3,'Tesla Revenue Automotive'!M24,'Tesla Revenue Automotive'!M32,'Tesla Revenue Automotive'!M40) -> 1.02 | N16: =CHOOSE(Drivers!$C$3,'Tesla Revenue Automotive'!N24,'Tesla Revenue Automotive'!N32,'Tesla Revenue Automotive'!N40) -> 1.02 | O16: =CHOOSE(Drivers!$C$3,'Tesla Revenue Automotive'!O24,'Tesla Revenue Automotive'!O32,'Tesla Revenue Automotive'!O40) -> 1.02 | ... Q16: =CHOOSE(Drivers!$C$3,'Tesla Revenue Automotive'!Q24,'Tesla Revenue Automotive'!Q32,'Tesla Revenue Automotive'!Q40) -> 1.02
B17: Tesla Roadster 2 | H17: =CHOOSE(Drivers!$C$3,'Tesla Revenue Automotive'!H25,'Tesla Revenue Automotive'!H33,'Tesla Revenue Automotive'!H41) -> 1.02 | I17: =CHOOSE(Drivers!$C$3,'Tesla Revenue Automotive'!I25,'Tesla Revenue Automotive'!I33,'Tesla Revenue Automotive'!I41) -> 1.02 | J17: =CHOOSE(Drivers!$C$3,'Tesla Revenue Automotive'!J25,'Tesla Revenue Automotive'!J33,'Tesla Revenue Automotive'!J41) -> 1.02 | K17: =CHOOSE(Drivers!$C$3,'Tesla Revenue Automotive'!K25,'Tesla Revenue Automotive'!K33,'Tesla Revenue Automotive'!K41) -> 1.02 | L17: =CHOOSE(Drivers!$C$3,'Tesla Revenue Automotive'!L25,'Tesla Revenue Automotive'!L33,'Tesla Revenue Automotive'!L41) -> 1.02 | M17: =CHOOSE(Drivers!$C$3,'Tesla Revenue Automotive'!M25,'Tesla Revenue Automotive'!M33,'Tesla Revenue Automotive'!M41) -> 1.02 | N17: =CHOOSE(Drivers!$C$3,'Tesla Revenue Automotive'!N25,'Tesla Revenue Automotive'!N33,'Tesla Revenue Automotive'!N41) -> 1.02 | O17: =CHOOSE(Drivers!$C$3,'Tesla Revenue Automotive'!O25,'Tesla Revenue Automotive'!O33,'Tesla Revenue Automotive'!O41) -> 1.02 | ... Q17: =CHOOSE(Drivers!$C$3,'Tesla Revenue Automotive'!Q25,'Tesla Revenue Automotive'!Q33,'Tesla Revenue Automotive'!Q41) -> 1.02
B18: Tesla Pickup | H18: =CHOOSE(Drivers!$C$3,'Tesla Revenue Automotive'!H26,'Tesla Revenue Automotive'!H34,'Tesla Revenue Automotive'!H42) -> 1.02 | I18: =CHOOSE(Drivers!$C$3,'Tesla Revenue Automotive'!I26,'Tesla Revenue Automotive'!I34,'Tesla Revenue Automotive'!I42) -> 1.02 | J18: =CHOOSE(Drivers!$C$3,'Tesla Revenue Automotive'!J26,'Tesla Revenue Automotive'!J34,'Tesla Revenue Automotive'!J42) -> 1.02 | K18: =CHOOSE(Drivers!$C$3,'Tesla Revenue Automotive'!K26,'Tesla Revenue Automotive'!K34,'Tesla Revenue Automotive'!K42) -> 1.02 | L18: =CHOOSE(Drivers!$C$3,'Tesla Revenue Automotive'!L26,'Tesla Revenue Automotive'!L34,'Tesla Revenue Automotive'!L42) -> 1.02 | M18: =CHOOSE(Drivers!$C$3,'Tesla Revenue Automotive'!M26,'Tesla Revenue Automotive'!M34,'Tesla Revenue Automotive'!M42) -> 1.02 | N18: =CHOOSE(Drivers!$C$3,'Tesla Revenue Automotive'!N26,'Tesla Revenue Automotive'!N34,'Tesla Revenue Automotive'!N42) -> 1.02 | O18: =CHOOSE(Drivers!$C$3,'Tesla Revenue Automotive'!O26,'Tesla Revenue Automotive'!O34,'Tesla Revenue Automotive'!O42) -> 1.02 | ... Q18: =CHOOSE(Drivers!$C$3,'Tesla Revenue Automotive'!Q26,'Tesla Revenue Automotive'!Q34,'Tesla Revenue Automotive'!Q42) -> 1.02
B19: Tesla Semi | H19: =CHOOSE(Drivers!$C$3,'Tesla Revenue Automotive'!H27,'Tesla Revenue Automotive'!H35,'Tesla Revenue Automotive'!H43) -> 1.02 | I19: =CHOOSE(Drivers!$C$3,'Tesla Revenue Automotive'!I27,'Tesla Revenue Automotive'!I35,'Tesla Revenue Automotive'!I43) -> 1.02 | J19: =CHOOSE(Drivers!$C$3,'Tesla Revenue Automotive'!J27,'Tesla Revenue Automotive'!J35,'Tesla Revenue Automotive'!J43) -> 1.02 | K19: =CHOOSE(Drivers!$C$3,'Tesla Revenue Automotive'!K27,'Tesla Revenue Automotive'!K35,'Tesla Revenue Automotive'!K43) -> 1.02 | L19: =CHOOSE(Drivers!$C$3,'Tesla Revenue Automotive'!L27,'Tesla Revenue Automotive'!L35,'Tesla Revenue Automotive'!L43) -> 1.02 | M19: =CHOOSE(Drivers!$C$3,'Tesla Revenue Automotive'!M27,'Tesla Revenue Automotive'!M35,'Tesla Revenue Automotive'!M43) -> 1.02 | N19: =CHOOSE(Drivers!$C$3,'Tesla Revenue Automotive'!N27,'Tesla Revenue Automotive'!N35,'Tesla Revenue Automotive'!N43) -> 1.02 | O19: =CHOOSE(Drivers!$C$3,'Tesla Revenue Automotive'!O27,'Tesla Revenue Automotive'!O35,'Tesla Revenue Automotive'!O43) -> 1.02 | ... Q19: =CHOOSE(Drivers!$C$3,'Tesla Revenue Automotive'!Q27,'Tesla Revenue Automotive'!Q35,'Tesla Revenue Automotive'!Q43) -> 1.02
B21: Best case
B22: Tesla Model 3 | H22: 1.02 | I22: 1.02 | J22: 1.02 | K22: 1.02 | L22: 1.02 | M22: 1.02 | N22: 1.02 | O22: 1.02 | P22: 1.02 | Q22: 1.02
B23: Tesla Model S and X | H23: 1.02 | I23: 1.02 | J23: 1.02 | K23: 1.02 | L23: 1.02 | M23: 1.02 | N23: 1.02 | O23: 1.02 | P23: 1.02 | Q23: 1.02
B24: Tesla Model Y | H24: 1.02 | I24: 1.02 | J24: 1.02 | K24: 1.02 | L24: 1.02 | M24: 1.02 | N24: 1.02 | O24: 1.02 | P24: 1.02 | Q24: 1.02
B25: Tesla Roadster 2 | H25: 1.02 | I25: 1.02 | J25: 1.02 | K25: 1.02 | L25: 1.02 | M25: 1.02 | N25: 1.02 | O25: 1.02 | P25: 1.02 | Q25: 1.02
B26: Tesla Pickup | H26: 1.02 | I26: 1.02 | J26: 1.02 | K26: 1.02 | L26: 1.02 | M26: 1.02 | N26: 1.02 | O26: 1.02 | P26: 1.02 | Q26: 1.02
B27: Tesla Semi | H27: 1.02 | I27: 1.02 | J27: 1.02 | K27: 1.02 | L27: 1.02 | M27: 1.02 | N27: 1.02 | O27: 1.02 | P27: 1.02 | Q27: 1.02
B29: Base case
B30: Tesla Model 3 | H30: 1 | I30: 1 | J30: 1 | K30: 1 | L30: 1 | M30: 1 | N30: 1 | O30: 1 | P30: 1 | Q30: 1
B31: Tesla Model S and X | H31: 1 | I31: 1 | J31: 1 | K31: 1 | L31: 1 | M31: 1 | N31: 1 | O31: 1 | P31: 1 | Q31: 1
B32: Tesla Model Y | H32: 1 | I32: 1 | J32: 1 | K32: 1 | L32: 1 | M32: 1 | N32: 1 | O32: 1 | P32: 1 | Q32: 1
B33: Tesla Roadster 2 | H33: 1 | I33: 1 | J33: 1 | K33: 1 | L33: 1 | M33: 1 | N33: 1 | O33: 1 | P33: 1 | Q33: 1
B34: Tesla Pickup | H34: 1 | I34: 1 | J34: 1 | K34: 1 | L34: 1 | M34: 1 | N34: 1 | O34: 1 | P34: 1 | Q34: 1
B35: Tesla Semi | H35: 1 | I35: 1 | J35: 1 | K35: 1 | L35: 1 | M35: 1 | N35: 1 | O35: 1 | P35: 1 | Q35: 1
B37: Worst case
B38: Tesla Model 3 | H38: 0.98 | I38: 0.98 | J38: 0.98 | K38: 0.98 | L38: 0.98 | M38: 0.98 | N38: 0.98 | O38: 0.98 | P38: 0.98 | Q38: 0.98
B39: Tesla Model S and X | H39: 0.98 | I39: 0.98 | J39: 0.98 | K39: 0.98 | L39: 0.98 | M39: 0.98 | N39: 0.98 | O39: 0.98 | P39: 0.98 | Q39: 0.98
B40: Tesla Model Y | H40: 0.98 | I40: 0.98 | J40: 0.98 | K40: 0.98 | L40: 0.98 | M40: 0.98 | N40: 0.98 | O40: 0.98 | P40: 0.98 | Q40: 0.98
B41: Tesla Roadster 2 | H41: 0.98 | I41: 0.98 | J41: 0.98 | K41: 0.98 | L41: 0.98 | M41: 0.98 | N41: 0.98 | O41: 0.98 | P41: 0.98 | Q41: 0.98
B42: Tesla Pickup | H42: 0.98 | I42: 0.98 | J42: 0.98 | K42: 0.98 | L42: 0.98 | M42: 0.98 | N42: 0.98 | O42: 0.98 | P42: 0.98 | Q42: 0.98
B43: Tesla Semi | H43: 0.98 | I43: 0.98 | J43: 0.98 | K43: 0.98 | L43: 0.98 | M43: 0.98 | N43: 0.98 | O43: 0.98 | P43: 0.98 | Q43: 0.98

Sheet Tesla Automotivo GP% 
B1: Tesla Automotive Gross Profit Margin %
B3: Comparables 2019
B5: Vehicle | C5: Comparable companies | D5: GP % Comp. 1 | E5: GP % Comp. 2 | F5: GP % Comp. 3 | H5: Average
B6: Tesla Model 3 | C6: GM, Ford, Fiat Chrysler | D6: 0.187 | E6: =(((155900-134693)/155900)+((160338-136269)/160338))/2 -> 0.14307182 | F6: =(((108187-93164)/108187)+((110412-95011)/110412))/2 -> 0.13917403 | H6: =C16 -> 0.22344388 | I6: Historic
B7: Tesla Model S and X | C7: BMW, Mercedes Cars, Volkswagen | D7: =((13620/91682)+(13928/85846))/2 -> 0.15540049 | E7: =((33067/167362)+(29165/172745))/2 -> 0.18320519 | F7: 0.172 | H7: =C17 -> 0.22344388 | I7: Historic
B8: Tesla Model Y | C8: GM, Ford, Fiat Chrysler | D8: 0.187 | E8: =(((155900-134693)/155900)+((160338-136269)/160338))/2 -> 0.14307182 | F8: =(((108187-93164)/108187)+((110412-95011)/110412))/2 -> 0.13917403 | H8: =AVERAGE(D8:F8) -> 0.15641528 | I8: Comparables
B9: Tesla Roadster 2 | C9: Jaguar, Porsche, Ferrari | D9: =(((24214-15670)/24214)+((25786-16328)/25786))/2 -> 0.35982095 | E9: 0.44 | F9: =(((3766-1805)/3766)+((3420-1623)/3420))/2 -> 0.52307511 | H9: =AVERAGE(D9:F9) -> 0.44096535 | I9: Comparables
B10: Tesla Pickup | C10: GM, Ford, Fiat Chrysler | D10: =D6 -> 0.187 | E10: =E6 -> 0.14307182 | F10: =F6 -> 0.13917403 | H10: =AVERAGE(D10:F10) -> 0.15641528 | I10: Comparables
B11: Tesla Semi | C11: Scania, MAN, Paccar | D11: 0.23 | E11: 0.23 | F11: =(((24120-20556)/24120)+((22139-18925)/22139))/2 -> 0.14646743 | H11: =AVERAGE(D11:F11) -> 0.20215581 | I11: Comparables
B13: Historical
B15: Vehicle | C15: Historic Average GP%
B16: Tesla Model 3 | C16: =AVERAGE('P&L Input'!F29:G29) -> 0.22344388
B17: Tesla Model S and X | C17: =AVERAGE('P&L Input'!F29:G29) -> 0.22344388
B18: Tesla Model Y | C18: n.a.
B19: Tesla Roadster 2 | C19: n.a.
B20: Tesla Pickup | C20: n.a.
B21: Tesla Semi | C21: n.a.

Sheet Tesla Automotive GP 
B1: Tesla Automotive Gross Profit
B3: Tesla Gross Profit (in mln $)
B4: Vehicle | C4: 2015 Act | D4: 2016 Act | E4: 2017 Act | F4: 2018 Act | G4: 2019 Act | H4: 2020 Fcst | I4: 2021 Fcst | J4: 2022 Fcst | K4: 2023 Fcst | L4: 2024 Fcst | M4: 2025 Fcst | N4: 2026 Fcst | O4: 2027 Fcst | P4: 2028 Fcst | Q4: 2029 Fcst
B5: Tesla Model 3 | C5: n.a. | D5: n.a. | E5: n.a. | F5: n.a. | G5: n.a. | H5: =H14*'Tesla Revenue Automotive'!H5 -> 6339.5401 | I5: =I14*'Tesla Revenue Automotive'!I5 -> 6973.4941 | J5: =J14*'Tesla Revenue Automotive'!J5 -> 7670.8435 | K5: =K14*'Tesla Revenue Automotive'!K5 -> 8284.511 | L5: =L14*'Tesla Revenue Automotive'!L5 -> 8947.2719 | M5: =M14*'Tesla Revenue Automotive'!M5 -> 9305.1628 | N5: =N14*'Tesla Revenue Automotive'!N5 -> 9677.3693 | O5: =O14*'Tesla Revenue Automotive'!O5 -> 10064.464 | ... Q5: =Q14*'Tesla Revenue Automotive'!Q5 -> 10885.724
B6: Tesla Model S and X | C6: n.a. | D6: n.a. | E6: n.a. | F6: n.a. | G6: n.a. | H6: =H15*'Tesla Revenue Automotive'!H6 -> 1713.6152 | I6: =I15*'Tesla Revenue Automotive'!I6 -> 1782.1598 | J6: =J15*'Tesla Revenue Automotive'!J6 -> 1853.4462 | K6: =K15*'Tesla Revenue Automotive'!K6 -> 1927.584 | L6: =L15*'Tesla Revenue Automotive'!L6 -> 2004.6874 | M6: =M15*'Tesla Revenue Automotive'!M6 -> 2084.8749 | N6: =N15*'Tesla Revenue Automotive'!N6 -> 2168.2699 | O6: =O15*'Tesla Revenue Automotive'!O6 -> 2255.0007 | ... Q6: =Q15*'Tesla Revenue Automotive'!Q6 -> 2439.0087
B7: Tesla Model Y | C7: 0 | D7: 0 | E7: 0 | F7: 0 | G7: =G16*'Tesla Revenue Automotive'!G7 -> 0 | H7: =H16*'Tesla Revenue Automotive'!H7 -> 18.81387 | I7: =I16*'Tesla Revenue Automotive'!I7 -> 1557.7436 | J7: =J16*'Tesla Revenue Automotive'!J7 -> 3208.33 | K7: =K16*'Tesla Revenue Automotive'!K7 -> 5133.3281 | L7: =L16*'Tesla Revenue Automotive'!L7 -> 5646.6609 | M7: =M16*'Tesla Revenue Automotive'!M7 -> 6211.327 | N7: =N16*'Tesla Revenue Automotive'!N7 -> 6708.2331 | ... Q7: =Q16*'Tesla Revenue Automotive'!Q7 -> 7836.0749
B8: Tesla Roadster 2 | C8: 0 | D8: 0 | E8: 0 | F8: 0 | G8: =G17*'Tesla Revenue Automotive'!G8 -> 0 | H8: - | I8: - | J8: =J17*'Tesla Revenue Automotive'!J8 -> 52.322024 | K8: =K17*'Tesla Revenue Automotive'!K8 -> 104.64405 | L8: =L17*'Tesla Revenue Automotive'!L8 -> 156.96607 | M8: =M17*'Tesla Revenue Automotive'!M8 -> 172.66268 | N8: =N17*'Tesla Revenue Automotive'!N8 -> 189.92895 | O8: =O17*'Tesla Revenue Automotive'!O8 -> 205.12326 | P8: =P17*'Tesla Revenue Automotive'!P8 -> 221.53313 | Q8: =Q17*'Tesla Revenue Automotive'!Q8 -> 230.39445
B9: Tesla Pickup | C9: 0 | D9: 0 | E9: 0 | F9: 0 | G9: =G18*'Tesla Revenue Automotive'!G9 -> 0 | H9: - | I9: =I18*'Tesla Revenue Automotive'!I9 -> 2.5527164 | J9: =J18*'Tesla Revenue Automotive'!J9 -> 211.35884 | K9: =K18*'Tesla Revenue Automotive'!K9 -> 435.31485 | L9: =L18*'Tesla Revenue Automotive'!L9 -> 696.50375 | M9: =M18*'Tesla Revenue Automotive'!M9 -> 766.15413 | N9: =N18*'Tesla Revenue Automotive'!N9 -> 842.76954 | O9: =O18*'Tesla Revenue Automotive'!O9 -> 910.1911 | P9: =P18*'Tesla Revenue Automotive'!P9 -> 983.00639 | Q9: =Q18*'Tesla Revenue Automotive'!Q9 -> 1022.3266
B10: Tesla Semi | C10: 0 | D10: 0 | E10: 0 | F10: 0 | G10: =G19*'Tesla Revenue Automotive'!G10 -> 0 | H10: - | I10: =I19*'Tesla Revenue Automotive'!I10 -> 9.6905781 | J10: =J19*'Tesla Revenue Automotive'!J10 -> 802.35679 | K10: =K19*'Tesla Revenue Automotive'!K10 -> 1652.5347 | L10: =L19*'Tesla Revenue Automotive'!L10 -> 2644.0556 | M10: =M19*'Tesla Revenue Automotive'!M10 -> 2908.4611 | N10: =N19*'Tesla Revenue Automotive'!N10 -> 3199.3072 | O10: =O19*'Tesla Revenue Automotive'!O10 -> 3455.2518 | P10: =P19*'Tesla Revenue Automotive'!P10 -> 3731.6719 | Q10: =Q19*'Tesla Revenue Automotive'!Q10 -> 3880.9388
B11: Total | C11: =('P&L Input'!C4+'P&L Input'!C8)/1000 -> 917.671 | D11: =('P&L Input'!D4+'P&L Input'!D8)/1000 -> 1600.685 | E11: =('P&L Input'!E4+'P&L Input'!E8)/1000 -> 2208.596 | F11: =('P&L Input'!F4+'P&L Input'!F8)/1000 -> 4340.986 | G11: =('P&L Input'!G4+'P&L Input'!G8)/1000 -> 4423 | H11: =SUM(H5:H10) -> 8071.9692 | I11: =SUM(I5:I10) -> 10325.641 | J11: =SUM(J5:J10) -> 13798.657 | K11: =SUM(K5:K10) -> 17537.917 | L11: =SUM(L5:L10) -> 20096.146 | M11: =SUM(M5:M10) -> 21448.643 | N11: =SUM(N5:N10) -> 22785.878 | O11: =SUM(O5:O10) -> 24134.923 | ... Q11: =SUM(Q5:Q10) -> 26294.468
B13: Selected case
B14: Tesla Model 3 | G14: =CHOOSE(Drivers!$C$3,'Tesla Automotive GP '!G22,'Tesla Automotive GP '!G30,'Tesla Automotive GP '!G38) -> 0.23844388 | H14: =CHOOSE(Drivers!$C$3,'Tesla Automotive GP '!H22,'Tesla Automotive GP '!H30,'Tesla Automotive GP '!H38) -> 0.23844388 | I14: =CHOOSE(Drivers!$C$3,'Tesla Automotive GP '!I22,'Tesla Automotive GP '!I30,'Tesla Automotive GP '!I38) -> 0.23844388 | J14: =CHOOSE(Drivers!$C$3,'Tesla Automotive GP '!J22,'Tesla Automotive GP '!J30,'Tesla Automotive GP '!J38) -> 0.23844388 | K14: =CHOOSE(Drivers!$C$3,'Tesla Automotive GP '!K22,'Tesla Automotive GP '!K30,'Tesla Automotive GP '!K38) -> 0.23844388 | L14: =CHOOSE(Drivers!$C$3,'Tesla Automotive GP '!L22,'Tesla Automotive GP '!L30,'Tesla Automotive GP '!L38) -> 0.23844388 | M14: =CHOOSE(Drivers!$C$3,'Tesla Automotive GP '!M22,'Tesla Automotive GP '!M30,'Tesla Automotive GP '!M38) -> 0.23844388 | N14: =CHOOSE(Drivers!$C$3,'Tesla Automotive GP '!N22,'Tesla Automotive GP '!N30,'Tesla Automotive GP '!N38) -> 0.23844388 | ... Q14: =CHOOSE(Drivers!$C$3,'Tesla Automotive GP '!Q22,'Tesla Automotive GP '!Q30,'Tesla Automotive GP '!Q38) -> 0.23844388
B15: Tesla Model S and X | G15: =CHOOSE(Drivers!$C$3,'Tesla Automotive GP '!G23,'Tesla Automotive GP '!G31,'Tesla Automotive GP '!G39) -> 0.23844388 | H15: =CHOOSE(Drivers!$C$3,'Tesla Automotive GP '!H23,'Tesla Automotive GP '!H31,'Tesla Automotive GP '!H39) -> 0.23844388 | I15: =CHOOSE(Drivers!$C$3,'Tesla Automotive GP '!I23,'Tesla Automotive GP '!I31,'Tesla Automotive GP '!I39) -> 0.23844388 | J15: =CHOOSE(Drivers!$C$3,'Tesla Automotive GP '!J23,'Tesla Automotive GP '!J31,'Tesla Automotive GP '!J39) -> 0.23844388 | K15: =CHOOSE(Drivers!$C$3,'Tesla Automotive GP '!K23,'Tesla Automotive GP '!K31,'Tesla Automotive GP '!K39) -> 0.23844388 | L15: =CHOOSE(Drivers!$C$3,'Tesla Automotive GP '!L23,'Tesla Automotive GP '!L31,'Tesla Automotive GP '!L39) -> 0.23844388 | M15: =CHOOSE(Drivers!$C$3,'Tesla Automotive GP '!M23,'Tesla Automotive GP '!M31,'Tesla Automotive GP '!M39) -> 0.23844388 | N15: =CHOOSE(Drivers!$C$3,'Tesla Automotive GP '!N23,'Tesla Automotive GP '!N31,'Tesla Automotive GP '!N39) -> 0.23844388 | ... Q15: =CHOOSE(Drivers!$C$3,'Tesla Automotive GP '!Q23,'Tesla Automotive GP '!Q31,'Tesla Automotive GP '!Q39) -> 0.23844388
B16: Tesla Model Y | G16: =CHOOSE(Drivers!$C$3,'Tesla Automotive GP '!G24,'Tesla Automotive GP '!G32,'Tesla Automotive GP '!G40) -> 0.17141528 | H16: =CHOOSE(Drivers!$C$3,'Tesla Automotive GP '!H24,'Tesla Automotive GP '!H32,'Tesla Automotive GP '!H40) -> 0.17141528 | I16: =CHOOSE(Drivers!$C$3,'Tesla Automotive GP '!I24,'Tesla Automotive GP '!I32,'Tesla Automotive GP '!I40) -> 0.17141528 | J16: =CHOOSE(Drivers!$C$3,'Tesla Automotive GP '!J24,'Tesla Automotive GP '!J32,'Tesla Automotive GP '!J40) -> 0.17141528 | K16: =CHOOSE(Drivers!$C$3,'Tesla Automotive GP '!K24,'Tesla Automotive GP '!K32,'Tesla Automotive GP '!K40) -> 0.17141528 | L16: =CHOOSE(Drivers!$C$3,'Tesla Automotive GP '!L24,'Tesla Automotive GP '!L32,'Tesla Automotive GP '!L40) -> 0.17141528 | M16: =CHOOSE(Drivers!$C$3,'Tesla Automotive GP '!M24,'Tesla Automotive GP '!M32,'Tesla Automotive GP '!M40) -> 0.17141528 | N16: =CHOOSE(Drivers!$C$3,'Tesla Automotive GP '!N24,'Tesla Automotive GP '!N32,'Tesla Automotive GP '!N40) -> 0.17141528 | ... Q16: =CHOOSE(Drivers!$C$3,'Tesla Automotive GP '!Q24,'Tesla Automotive GP '!Q32,'Tesla Automotive GP '!Q40) -> 0.17141528
B17: Tesla Roadster 2 | G17: =CHOOSE(Drivers!$C$3,'Tesla Automotive GP '!G25,'Tesla Automotive GP '!G33,'Tesla Automotive GP '!G41) -> 0.45596535 | H17: =CHOOSE(Drivers!$C$3,'Tesla Automotive GP '!H25,'Tesla Automotive GP '!H33,'Tesla Automotive GP '!H41) -> 0.45596535 | I17: =CHOOSE(Drivers!$C$3,'Tesla Automotive GP '!I25,'Tesla Automotive GP '!I33,'Tesla Automotive GP '!I41) -> 0.45596535 | J17: =CHOOSE(Drivers!$C$3,'Tesla Automotive GP '!J25,'Tesla Automotive GP '!J33,'Tesla Automotive GP '!J41) -> 0.45596535 | K17: =CHOOSE(Drivers!$C$3,'Tesla Automotive GP '!K25,'Tesla Automotive GP '!K33,'Tesla Automotive GP '!K41) -> 0.45596535 | L17: =CHOOSE(Drivers!$C$3,'Tesla Automotive GP '!L25,'Tesla Automotive GP '!L33,'Tesla Automotive GP '!L41) -> 0.45596535 | M17: =CHOOSE(Drivers!$C$3,'Tesla Automotive GP '!M25,'Tesla Automotive GP '!M33,'Tesla Automotive GP '!M41) -> 0.45596535 | N17: =CHOOSE(Drivers!$C$3,'Tesla Automotive GP '!N25,'Tesla Automotive GP '!N33,'Tesla Automotive GP '!N41) -> 0.45596535 | ... Q17: =CHOOSE(Drivers!$C$3,'Tesla Automotive GP '!Q25,'Tesla Automotive GP '!Q33,'Tesla Automotive GP '!Q41) -> 0.45596535
B18: Tesla Pickup | G18: =CHOOSE(Drivers!$C$3,'Tesla Automotive GP '!G26,'Tesla Automotive GP '!G34,'Tesla Automotive GP '!G42) -> 0.17141528 | H18: =CHOOSE(Drivers!$C$3,'Tesla Automotive GP '!H26,'Tesla Automotive GP '!H34,'Tesla Automotive GP '!H42) -> 0.17141528 | I18: =CHOOSE(Drivers!$C$3,'Tesla Automotive GP '!I26,'Tesla Automotive GP '!I34,'Tesla Automotive GP '!I42) -> 0.17141528 | J18: =CHOOSE(Drivers!$C$3,'Tesla Automotive GP '!J26,'Tesla Automotive GP '!J34,'Tesla Automotive GP '!J42) -> 0.17141528 | K18: =CHOOSE(Drivers!$C$3,'Tesla Automotive GP '!K26,'Tesla Automotive GP '!K34,'Tesla Automotive GP '!K42) -> 0.17141528 | L18: =CHOOSE(Drivers!$C$3,'Tesla Automotive GP '!L26,'Tesla Automotive GP '!L34,'Tesla Automotive GP '!L42) -> 0.17141528 | M18: =CHOOSE(Drivers!$C$3,'Tesla Automotive GP '!M26,'Tesla Automotive GP '!M34,'Tesla Automotive GP '!M42) -> 0.17141528 | N18: =CHOOSE(Drivers!$C$3,'Tesla Automotive GP '!N26,'Tesla Automotive GP '!N34,'Tesla Automotive GP '!N42) -> 0.17141528 | ... Q18: =CHOOSE(Drivers!$C$3,'Tesla Automotive GP '!Q26,'Tesla Automotive GP '!Q34,'Tesla Automotive GP '!Q42) -> 0.17141528
B19: Tesla Semi | G19: =CHOOSE(Drivers!$C$3,'Tesla Automotive GP '!G27,'Tesla Automotive GP '!G35,'Tesla Automotive GP '!G43) -> 0.21715581 | H19: =CHOOSE(Drivers!$C$3,'Tesla Automotive GP '!H27,'Tesla Automotive GP '!H35,'Tesla Automotive GP '!H43) -> 0.21715581 | I19: =CHOOSE(Drivers!$C$3,'Tesla Automotive GP '!I27,'Tesla Automotive GP '!I35,'Tesla Automotive GP '!I43) -> 0.21715581 | J19: =CHOOSE(Drivers!$C$3,'Tesla Automotive GP '!J27,'Tesla Automotive GP '!J35,'Tesla Automotive GP '!J43) -> 0.21715581 | K19: =CHOOSE(Drivers!$C$3,'Tesla Automotive GP '!K27,'Tesla Automotive GP '!K35,'Tesla Automotive GP '!K43) -> 0.21715581 | L19: =CHOOSE(Drivers!$C$3,'Tesla Automotive GP '!L27,'Tesla Automotive GP '!L35,'Tesla Automotive GP '!L43) -> 0.21715581 | M19: =CHOOSE(Drivers!$C$3,'Tesla Automotive GP '!M27,'Tesla Automotive GP '!M35,'Tesla Automotive GP '!M43) -> 0.21715581 | N19: =CHOOSE(Drivers!$C$3,'Tesla Automotive GP '!N27,'Tesla Automotive GP '!N35,'Tesla Automotive GP '!N43) -> 0.21715581 | ... Q19: =CHOOSE(Drivers!$C$3,'Tesla Automotive GP '!Q27,'Tesla Automotive GP '!Q35,'Tesla Automotive GP '!Q43) -> 0.21715581
B21: Best case
B22: Tesla Model 3 | G22: =G30+1.5% -> 0.23844388 | H22: =H30+1.5% -> 0.23844388 | I22: =I30+1.5% -> 0.23844388 | J22: =J30+1.5% -> 0.23844388 | K22: =K30+1.5% -> 0.23844388 | L22: =L30+1.5% -> 0.23844388 | M22: =M30+1.5% -> 0.23844388 | N22: =N30+1.5% -> 0.23844388 | ... Q22: =Q30+1.5% -> 0.23844388
B23: Tesla Model S and X | G23: =G31+1.5% -> 0.23844388 | H23: =H31+1.5% -> 0.23844388 | I23: =I31+1.5% -> 0.23844388 | J23: =J31+1.5% -> 0.23844388 | K23: =K31+1.5% -> 0.23844388 | L23: =L31+1.5% -> 0.23844388 | M23: =M31+1.5% -> 0.23844388 | N23: =N31+1.5% -> 0.23844388 | ... Q23: =Q31+1.5% -> 0.23844388
B24: Tesla Model Y | G24: =G32+1.5% -> 0.17141528 | H24: =H32+1.5% -> 0.17141528 | I24: =I32+1.5% -> 0.17141528 | J24: =J32+1.5% -> 0.17141528 | K24: =K32+1.5% -> 0.17141528 | L24: =L32+1.5% -> 0.17141528 | M24: =M32+1.5% -> 0.17141528 | N24: =N32+1.5% -> 0.17141528 | ... Q24: =Q32+1.5% -> 0.17141528
B25: Tesla Roadster 2 | G25: =G33+1.5% -> 0.45596535 | H25: =H33+1.5% -> 0.45596535 | I25: =I33+1.5% -> 0.45596535 | J25: =J33+1.5% -> 0.45596535 | K25: =K33+1.5% -> 0.45596535 | L25: =L33+1.5% -> 0.45596535 | M25: =M33+1.5% -> 0.45596535 | N25: =N33+1.5% -> 0.45596535 | ... Q25: =Q33+1.5% -> 0.45596535
B26: Tesla Pickup | G26: =G34+1.5% -> 0.17141528 | H26: =H34+1.5% -> 0.17141528 | I26: =I34+1.5% -> 0.17141528 | J26: =J34+1.5% -> 0.17141528 | K26: =K34+1.5% -> 0.17141528 | L26: =L34+1.5% -> 0.17141528 | M26: =M34+1.5% -> 0.17141528 | N26: =N34+1.5% -> 0.17141528 | ... Q26: =Q34+1.5% -> 0.17141528
B27: Tesla Semi | G27: =G35+1.5% -> 0.21715581 | H27: =H35+1.5% -> 0.21715581 | I27: =I35+1.5% -> 0.21715581 | J27: =J35+1.5% -> 0.21715581 | K27: =K35+1.5% -> 0.21715581 | L27: =L35+1.5% -> 0.21715581 | M27: =M35+1.5% -> 0.21715581 | N27: =N35+1.5% -> 0.21715581 | ... Q27: =Q35+1.5% -> 0.21715581
B29: Base case
B30: Tesla Model 3 | G30: ='Tesla Automotivo GP% '!$H6 -> 0.22344388 | H30: ='Tesla Automotivo GP% '!$H6 -> 0.22344388 | I30: ='Tesla Automotivo GP% '!$H6 -> 0.22344388 | J30: ='Tesla Automotivo GP% '!$H6 -> 0.22344388 | K30: ='Tesla Automotivo GP% '!$H6 -> 0.22344388 | L30: ='Tesla Automotivo GP% '!$H6 -> 0.22344388 | M30: ='Tesla Automotivo GP% '!$H6 -> 0.22344388 | N30: ='Tesla Automotivo GP% '!$H6 -> 0.22344388 | ... Q30: ='Tesla Automotivo GP% '!$H6 -> 0.22344388
B31: Tesla Model S and X | G31: ='Tesla Automotivo GP% '!$H7 -> 0.22344388 | H31: ='Tesla Automotivo GP% '!$H7 -> 0.22344388 | I31: ='Tesla Automotivo GP% '!$H7 -> 0.22344388 | J31: ='Tesla Automotivo GP% '!$H7 -> 0.22344388 | K31: ='Tesla Automotivo GP% '!$H7 -> 0.22344388 | L31: ='Tesla Automotivo GP% '!$H7 -> 0.22344388 | M31: ='Tesla Automotivo GP% '!$H7 -> 0.22344388 | N31: ='Tesla Automotivo GP% '!$H7 -> 0.22344388 | ... Q31: ='Tesla Automotivo GP% '!$H7 -> 0.22344388
B32: Tesla Model Y | G32: ='Tesla Automotivo GP% '!$H8 -> 0.15641528 | H32: ='Tesla Automotivo GP% '!$H8 -> 0.15641528 | I32: ='Tesla Automotivo GP% '!$H8 -> 0.15641528 | J32: ='Tesla Automotivo GP% '!$H8 -> 0.15641528 | K32: ='Tesla Automotivo GP% '!$H8 -> 0.15641528 | L32: ='Tesla Automotivo GP% '!$H8 -> 0.15641528 | M32: ='Tesla Automotivo GP% '!$H8 -> 0.15641528 | N32: ='Tesla Automotivo GP% '!$H8 -> 0.15641528 | ... Q32: ='Tesla Automotivo GP% '!$H8 -> 0.15641528
B33: Tesla Roadster 2 | G33: ='Tesla Automotivo GP% '!$H9 -> 0.44096535 | H33: ='Tesla Automotivo GP% '!$H9 -> 0.44096535 | I33: ='Tesla Automotivo GP% '!$H9 -> 0.44096535 | J33: ='Tesla Automotivo GP% '!$H9 -> 0.44096535 | K33: ='Tesla Automotivo GP% '!$H9 -> 0.44096535 | L33: ='Tesla Automotivo GP% '!$H9 -> 0.44096535 | M33: ='Tesla Automotivo GP% '!$H9 -> 0.44096535 | N33: ='Tesla Automotivo GP% '!$H9 -> 0.44096535 | ... Q33: ='Tesla Automotivo GP% '!$H9 -> 0.44096535
B34: Tesla Pickup | G34: ='Tesla Automotivo GP% '!$H10 -> 0.15641528 | H34: ='Tesla Automotivo GP% '!$H10 -> 0.15641528 | I34: ='Tesla Automotivo GP% '!$H10 -> 0.15641528 | J34: ='Tesla Automotivo GP% '!$H10 -> 0.15641528 | K34: ='Tesla Automotivo GP% '!$H10 -> 0.15641528 | L34: ='Tesla Automotivo GP% '!$H10 -> 0.15641528 | M34: ='Tesla Automotivo GP% '!$H10 -> 0.15641528 | N34: ='Tesla Automotivo GP% '!$H10 -> 0.15641528 | ... Q34: ='Tesla Automotivo GP% '!$H10 -> 0.15641528
B35: Tesla Semi | G35: ='Tesla Automotivo GP% '!$H11 -> 0.20215581 | H35: ='Tesla Automotivo GP% '!$H11 -> 0.20215581 | I35: ='Tesla Automotivo GP% '!$H11 -> 0.20215581 | J35: ='Tesla Automotivo GP% '!$H11 -> 0.20215581 | K35: ='Tesla Automotivo GP% '!$H11 -> 0.20215581 | L35: ='Tesla Automotivo GP% '!$H11 -> 0.20215581 | M35: ='Tesla Automotivo GP% '!$H11 -> 0.20215581 | N35: ='Tesla Automotivo GP% '!$H11 -> 0.20215581 | ... Q35: ='Tesla Automotivo GP% '!$H11 -> 0.20215581
B37: Worst case
B38: Tesla Model 3 | G38: =G30-1.5% -> 0.20844388 | H38: =H30-1.5% -> 0.20844388 | I38: =I30-1.5% -> 0.20844388 | J38: =J30-1.5% -> 0.20844388 | K38: =K30-1.5% -> 0.20844388 | L38: =L30-1.5% -> 0.20844388 | M38: =M30-1.5% -> 0.20844388 | N38: =N30-1.5% -> 0.20844388 | ... Q38: =Q30-1.5% -> 0.20844388
B39: Tesla Model S and X | G39: =G31-1.5% -> 0.20844388 | H39: =H31-1.5% -> 0.20844388 | I39: =I31-1.5% -> 0.20844388 | J39: =J31-1.5% -> 0.20844388 | K39: =K31-1.5% -> 0.20844388 | L39: =L31-1.5% -> 0.20844388 | M39: =M31-1.5% -> 0.20844388 | N39: =N31-1.5% -> 0.20844388 | ... Q39: =Q31-1.5% -> 0.20844388
B40: Tesla Model Y | G40: =G32-1.5% -> 0.14141528 | H40: =H32-1.5% -> 0.14141528 | I40: =I32-1.5% -> 0.14141528 | J40: =J32-1.5% -> 0.14141528 | K40: =K32-1.5% -> 0.14141528 | L40: =L32-1.5% -> 0.14141528 | M40: =M32-1.5% -> 0.14141528 | N40: =N32-1.5% -> 0.14141528 | ... Q40: =Q32-1.5% -> 0.14141528
B41: Tesla Roadster 2 | G41: =G33-1.5% -> 0.42596535 | H41: =H33-1.5% -> 0.42596535 | I41: =I33-1.5% -> 0.42596535 | J41: =J33-1.5% -> 0.42596535 | K41: =K33-1.5% -> 0.42596535 | L41: =L33-1.5% -> 0.42596535 | M41: =M33-1.5% -> 0.42596535 | N41: =N33-1.5% -> 0.42596535 | ... Q41: =Q33-1.5% -> 0.42596535
B42: Tesla Pickup | G42: =G34-1.5% -> 0.14141528 | H42: =H34-1.5% -> 0.14141528 | I42: =I34-1.5% -> 0.14141528 | J42: =J34-1.5% -> 0.14141528 | K42: =K34-1.5% -> 0.14141528 | L42: =L34-1.5% -> 0.14141528 | M42: =M34-1.5% -> 0.14141528 | N42: =N34-1.5% -> 0.14141528 | ... Q42: =Q34-1.5% -> 0.14141528
B43: Tesla Semi | G43: =G35-1.5% -> 0.18715581 | H43: =H35-1.5% -> 0.18715581 | I43: =I35-1.5% -> 0.18715581 | J43: =J35-1.5% -> 0.18715581 | K43: =K35-1.5% -> 0.18715581 | L43: =L35-1.5% -> 0.18715581 | M43: =M35-1.5% -> 0.18715581 | N43: =N35-1.5% -> 0.18715581 | ... Q43: =Q35-1.5% -> 0.18715581

Sheet Tesla Cost of sales Automotive
B1: Tesla Cost of sales Automotive
B3: Tesla Cost of sales (in mln $)
B4: Vehicle | C4: 2015 Act | D4: 2016 Act | E4: 2017 Act | F4: 2018 Act | G4: 2019 Act | H4: 2020 Fcst | I4: 2021 Fcst | J4: 2022 Fcst | K4: 2023 Fcst | L4: 2024 Fcst | M4: 2025 Fcst | N4: 2026 Fcst | O4: 2027 Fcst | P4: 2028 Fcst | Q4: 2029 Fcst
B5: Tesla Model 3 | C5: n.a. | D5: n.a. | E5: n.a. | F5: n.a. | G5: n.a. | H5: =-('Tesla Revenue Automotive'!H5-'Tesla Automotive GP '!H5) -> -20247.597 | I5: =-('Tesla Revenue Automotive'!I5-'Tesla Automotive GP '!I5) -> -22272.356 | J5: =-('Tesla Revenue Automotive'!J5-'Tesla Automotive GP '!J5) -> -24499.592 | K5: =-('Tesla Revenue Automotive'!K5-'Tesla Automotive GP '!K5) -> -26459.559 | L5: =-('Tesla Revenue Automotive'!L5-'Tesla Automotive GP '!L5) -> -28576.324 | M5: =-('Tesla Revenue Automotive'!M5-'Tesla Automotive GP '!M5) -> -29719.377 | N5: =-('Tesla Revenue Automotive'!N5-'Tesla Automotive GP '!N5) -> -30908.152 | O5: =-('Tesla Revenue Automotive'!O5-'Tesla Automotive GP '!O5) -> -32144.478 | ... Q5: =-('Tesla Revenue Automotive'!Q5-'Tesla Automotive GP '!Q5) -> -34767.468
B6: Tesla Model S and X | C6: n.a. | D6: n.a. | E6: n.a. | F6: n.a. | G6: n.a. | H6: =-('Tesla Revenue Automotive'!H6-'Tesla Automotive GP '!H6) -> -5473.0451 | I6: =-('Tesla Revenue Automotive'!I6-'Tesla Automotive GP '!I6) -> -5691.9669 | J6: =-('Tesla Revenue Automotive'!J6-'Tesla Automotive GP '!J6) -> -5919.6456 | K6: =-('Tesla Revenue Automotive'!K6-'Tesla Automotive GP '!K6) -> -6156.4314 | L6: =-('Tesla Revenue Automotive'!L6-'Tesla Automotive GP '!L6) -> -6402.6887 | M6: =-('Tesla Revenue Automotive'!M6-'Tesla Automotive GP '!M6) -> -6658.7963 | N6: =-('Tesla Revenue Automotive'!N6-'Tesla Automotive GP '!N6) -> -6925.1481 | O6: =-('Tesla Revenue Automotive'!O6-'Tesla Automotive GP '!O6) -> -7202.154 | ... Q6: =-('Tesla Revenue Automotive'!Q6-'Tesla Automotive GP '!Q6) -> -7789.8498
B7: Tesla Model Y | C7: 0 | D7: 0 | E7: 0 | F7: 0 | G7: =-('Tesla Revenue Automotive'!G7-'Tesla Automotive GP '!G7) -> 0 | H7: =-('Tesla Revenue Automotive'!H7-'Tesla Automotive GP '!H7) -> -90.94221 | I7: =-('Tesla Revenue Automotive'!I7-'Tesla Automotive GP '!I7) -> -7529.7985 | J7: =-('Tesla Revenue Automotive'!J7-'Tesla Automotive GP '!J7) -> -15508.379 | K7: =-('Tesla Revenue Automotive'!K7-'Tesla Automotive GP '!K7) -> -24813.407 | L7: =-('Tesla Revenue Automotive'!L7-'Tesla Automotive GP '!L7) -> -27294.747 | M7: =-('Tesla Revenue Automotive'!M7-'Tesla Automotive GP '!M7) -> -30024.222 | N7: =-('Tesla Revenue Automotive'!N7-'Tesla Automotive GP '!N7) -> -32426.16 | ... Q7: =-('Tesla Revenue Automotive'!Q7-'Tesla Automotive GP '!Q7) -> -37877.905
B8: Tesla Roadster 2 | C8: 0 | D8: 0 | E8: 0 | F8: 0 | G8: =-('Tesla Revenue Automotive'!G8-'Tesla Automotive GP '!G8) -> 0 | H8: - | I8: - | J8: =-('Tesla Revenue Automotive'!J8-'Tesla Automotive GP '!J8) -> -62.427976 | K8: =-('Tesla Revenue Automotive'!K8-'Tesla Automotive GP '!K8) -> -124.85595 | L8: =-('Tesla Revenue Automotive'!L8-'Tesla Automotive GP '!L8) -> -187.28393 | M8: =-('Tesla Revenue Automotive'!M8-'Tesla Automotive GP '!M8) -> -206.01232 | N8: =-('Tesla Revenue Automotive'!N8-'Tesla Automotive GP '!N8) -> -226.61355 | O8: =-('Tesla Revenue Automotive'!O8-'Tesla Automotive GP '!O8) -> -244.74264 | P8: =-('Tesla Revenue Automotive'!P8-'Tesla Automotive GP '!P8) -> -264.32205 | Q8: =-('Tesla Revenue Automotive'!Q8-'Tesla Automotive GP '!Q8) -> -274.89493
B9: Tesla Pickup | C9: 0 | D9: 0 | E9: 0 | F9: 0 | G9: =-('Tesla Revenue Automotive'!G9-'Tesla Automotive GP '!G9) -> 0 | H9: - | I9: =-('Tesla Revenue Automotive'!I9-'Tesla Automotive GP '!I9) -> -12.339284 | J9: =-('Tesla Revenue Automotive'!J9-'Tesla Automotive GP '!J9) -> -1021.6633 | K9: =-('Tesla Revenue Automotive'!K9-'Tesla Automotive GP '!K9) -> -2104.2186 | L9: =-('Tesla Revenue Automotive'!L9-'Tesla Automotive GP '!L9) -> -3366.7497 | M9: =-('Tesla Revenue Automotive'!M9-'Tesla Automotive GP '!M9) -> -3703.4247 | N9: =-('Tesla Revenue Automotive'!N9-'Tesla Automotive GP '!N9) -> -4073.7672 | O9: =-('Tesla Revenue Automotive'!O9-'Tesla Automotive GP '!O9) -> -4399.6686 | P9: =-('Tesla Revenue Automotive'!P9-'Tesla Automotive GP '!P9) -> -4751.642 | Q9: =-('Tesla Revenue Automotive'!Q9-'Tesla Automotive GP '!Q9) -> -4941.7077
B10: Tesla Semi | C10: 0 | D10: 0 | E10: 0 | F10: 0 | G10: =-('Tesla Revenue Automotive'!G10-'Tesla Automotive GP '!G10) -> 0 | H10: - | I10: =-('Tesla Revenue Automotive'!I10-'Tesla Automotive GP '!I10) -> -34.934422 | J10: =-('Tesla Revenue Automotive'!J10-'Tesla Automotive GP '!J10) -> -2892.487 | K10: =-('Tesla Revenue Automotive'!K10-'Tesla Automotive GP '!K10) -> -5957.3686 | L10: =-('Tesla Revenue Automotive'!L10-'Tesla Automotive GP '!L10) -> -9531.7897 | M10: =-('Tesla Revenue Automotive'!M10-'Tesla Automotive GP '!M10) -> -10484.969 | N10: =-('Tesla Revenue Automotive'!N10-'Tesla Automotive GP '!N10) -> -11533.466 | O10: =-('Tesla Revenue Automotive'!O10-'Tesla Automotive GP '!O10) -> -12456.143 | P10: =-('Tesla Revenue Automotive'!P10-'Tesla Automotive GP '!P10) -> -13452.634 | Q10: =-('Tesla Revenue Automotive'!Q10-'Tesla Automotive GP '!Q10) -> -13990.74
B11: Total | C11: ='P&L Input'!C8/1000 -> -2823.302 | D11: ='P&L Input'!D8/1000 -> -4750.081 | E11: ='P&L Input'!E8/1000 -> -7432.704 | F11: ='P&L Input'!F8/1000 -> -14173.997 | G11: ='P&L Input'!G8/1000 -> -16398 | H11: =SUM(H5:H10) -> -25811.584 | I11: =SUM(I5:I10) -> -35541.395 | J11: =SUM(J5:J10) -> -49904.195 | K11: =SUM(K5:K10) -> -65615.841 | L11: =SUM(L5:L10) -> -75359.584 | M11: =SUM(M5:M10) -> -80796.801 | N11: =SUM(N5:N10) -> -86093.306 | O11: =SUM(O5:O10) -> -91467.439 | ... Q11: =SUM(Q5:Q10) -> -99642.565

Sheet Revenue and GP Automative Chart
B1: Revenue and Gross Profit automotive
B3: Vehicle | C3: 2016 Act | D3: 2017 Act | E3: 2018 Act | F3: 2019 Act | G3: 2020 Fcst | H3: 2021 Fcst | I3: 2022 Fcst | J3: 2023 Fcst | K3: 2024 Fcst | L3: 2025 Fcst | M3: 2026 Fcst | N3: 2027 Fcst | O3: 2028 Fcst | P3: 2029 Fcst
B4: Revenue automotive | C4: ='Tesla Revenue Automotive'!D11 -> 6350.766 | D4: ='Tesla Revenue Automotive'!E11 -> 9641.3 | E4: ='Tesla Revenue Automotive'!F11 -> 18514.983 | F4: ='Tesla Revenue Automotive'!G11 -> 20821 | G4: ='Tesla Revenue Automotive'!H11 -> 33883.553 | H4: ='Tesla Revenue Automotive'!I11 -> 45867.036 | I4: ='Tesla Revenue Automotive'!J11 -> 63702.852 | J4: ='Tesla Revenue Automotive'!K11 -> 83153.757 | ... P4: ='Tesla Revenue Automotive'!Q11 -> 125937.03
B5: Gross Profit automotive | C5: ='Tesla Automotive GP '!D11 -> 1600.685 | D5: ='Tesla Automotive GP '!E11 -> 2208.596 | E5: ='Tesla Automotive GP '!F11 -> 4340.986 | F5: ='Tesla Automotive GP '!G11 -> 4423 | G5: ='Tesla Automotive GP '!H11 -> 8071.9692 | H5: ='Tesla Automotive GP '!I11 -> 10325.641 | I5: ='Tesla Automotive GP '!J11 -> 13798.657 | J5: ='Tesla Automotive GP '!K11 -> 17537.917 | ... P5: ='Tesla Automotive GP '!Q11 -> 26294.468
B6: GP% | C6: =C5/C4 -> 0.25204597 | D6: =D5/D4 -> 0.22907658 | E6: =E5/E4 -> 0.23445801 | F6: =F5/F4 -> 0.21242976 | G6: =G5/G4 -> 0.23822676 | H6: =H5/H4 -> 0.22512117 | I6: =I5/I4 -> 0.21660973 | J6: =J5/J4 -> 0.21090949 | ... P6: =P5/P4 -> 0.20879059

Sheet 2.Tesla Energy,Services & Other
A13: 2. Tesla Energy, Services & Other

Sheet Revenue Energy, service & Other
B1: Tesla Revenue Energy, Serivice & Other
B3: Tesla Revenue Energy & Other (in mln $)
B4: ($ in million) | C4: 2015 Act | D4: 2016 Act | E4: 2017 Act | F4: 2018 Act | G4: 2019 Act | H4: 2020 Fcst | I4: 2021 Fcst | J4: 2022 Fcst | K4: 2023 Fcst | L4: 2024 Fcst | M4: 2025 Fcst | N4: 2026 Fcst | O4: 2027 Fcst | P4: 2028 Fcst | Q4: 2029 Fcst
B5: Energy generation and storage | C5: ='P&L Input'!C5/1000 -> 14.477 | D5: ='P&L Input'!D5/1000 -> 181.394 | E5: ='P&L Input'!E5/1000 -> 1116.266 | F5: ='P&L Input'!F5/1000 -> 1555.244 | G5: ='P&L Input'!G5/1000 -> 1531 | H5: n.a. | I5: n.a. | J5: n.a. | K5: n.a. | L5: n.a. | M5: n.a. | N5: n.a. | O5: n.a. | P5: n.a. | Q5: n.a.
B6: Services and other | C6: ='P&L Input'!C6/1000 -> 290.575 | D6: ='P&L Input'!D6/1000 -> 467.972 | E6: ='P&L Input'!E6/1000 -> 1001.185 | F6: ='P&L Input'!F6/1000 -> 1391.041 | G6: ='P&L Input'!G6/1000 -> 2226 | H6: n.a. | I6: n.a. | J6: n.a. | K6: n.a. | L6: n.a. | M6: n.a. | N6: n.a. | O6: n.a. | P6: n.a. | Q6: n.a.
